Workbook

Sheet Sheet1
A1: State | B1: Account length | C1: Area code | D1: International plan | E1: Voice mail plan | F1: Number vmail messages | G1: Total day minutes | H1: Total day calls | I1: Total day charge | J1: Total eve minutes | K1: Total eve calls | L1: Total eve charge | M1: Total night minutes | N1: Total night calls | O1: Total night charge | P1: Total intl minutes | Q1: Total intl calls | R1: Total intl charge | S1: Customer service calls | T1: Churn | U1: High Usage | V1: Risk Customer | W1: Potential Churn | X1: Support Level | Y1: Region
A2: LA | B2: 117 | C2: 408 | D2: No | E2: No | F2: 0 | G2: 184.5 | H2: 97 | I2: 31.37 | J2: 351.6 | K2: 80 | L2: 29.89 | M2: 215.8 | N2: 90 | O2: 9.71 | P2: 8.7 | Q2: 4 | R2: 2.35 | S2: 1 | T2: FALSE | U2: =IF(G2>200,"High Usage","Normal Usage") -> Normal Usage | V2: =IF(AND(S2>3,D2="Yes"),"High Risk","Normal") -> Normal | W2: =IF(OR(S2>3,G2>250),"Potential Churn","Stable") -> Stable | X2: =IF(S2>5,"Critical",IF(S2>=3,"Medium","Low")) -> Low | Y2: =VLOOKUP(A2,A1:U668,2,FALSE) -> 117
A3: IN | B3: 65 | C3: 415 | D3: No | E3: No | F3: 0 | G3: 129.1 | H3: 137 | I3: 21.95 | J3: 228.5 | K3: 83 | L3: 19.42 | M3: 208.8 | N3: 111 | O3: 9.4 | P3: 12.7 | Q3: 6 | R3: 3.43 | S3: 4 | T3: TRUE | U3: =IF(G3>200,"High Usage","Normal Usage") -> Normal Usage | V3: =IF(AND(S3>3,D3="Yes"),"High Risk","Normal") -> Normal | W3: =IF(OR(S3>3,G3>250),"Potential Churn","Stable") -> Potential Churn | X3: =IF(S3>5,"Critical",IF(S3>=3,"Medium","Low")) -> Medium | Y3: =VLOOKUP(A3,A2:U669,2,FALSE) -> 65
A4: NY | B4: 161 | C4: 415 | D4: No | E4: No | F4: 0 | G4: 332.9 | H4: 67 | I4: 56.59 | J4: 317.8 | K4: 97 | L4: 27.01 | M4: 160.6 | N4: 128 | O4: 7.23 | P4: 5.4 | Q4: 9 | R4: 1.46 | S4: 4 | T4: TRUE | U4: =IF(G4>200,"High Usage","Normal Usage") -> High Usage | V4: =IF(AND(S4>3,D4="Yes"),"High Risk","Normal") -> Normal | W4: =IF(OR(S4>3,G4>250),"Potential Churn","Stable") -> Potential Churn | X4: =IF(S4>5,"Critical",IF(S4>=3,"Medium","Low")) -> Medium | Y4: =VLOOKUP(A4,A3:U670,2,FALSE) -> 161
A5: SC | B5: 111 | C5: 415 | D5: No | E5: No | F5: 0 | G5: 110.4 | H5: 103 | I5: 18.77 | J5: 137.3 | K5: 102 | L5: 11.67 | M5: 189.6 | N5: 105 | O5: 8.53 | P5: 7.7 | Q5: 6 | R5: 2.08 | S5: 2 | T5: FALSE | U5: =IF(G5>200,"High Usage","Normal Usage") -> Normal Usage | V5: =IF(AND(S5>3,D5="Yes"),"High Risk","Normal") -> Normal | W5: =IF(OR(S5>3,G5>250),"Potential Churn","Stable") -> Stable | X5: =IF(S5>5,"Critical",IF(S5>=3,"Medium","Low")) -> Low | Y5: =VLOOKUP(A5,A4:U671,2,FALSE) -> 111
A6: HI | B6: 49 | C6: 510 | D6: No | E6: No | F6: 0 | G6: 119.3 | H6: 117 | I6: 20.28 | J6: 215.1 | K6: 109 | L6: 18.28 | M6: 178.7 | N6: 90 | O6: 8.04 | P6: 11.1 | Q6: 1 | R6: 3 | S6: 1 | T6: FALSE | U6: =IF(G6>200,"High Usage","Normal Usage") -> Normal Usage | V6: =IF(AND(S6>3,D6="Yes"),"High Risk","Normal") -> Normal | W6: =IF(OR(S6>3,G6>250),"Potential Churn","Stable") -> Stable | X6: =IF(S6>5,"Critical",IF(S6>=3,"Medium","Low")) -> Low | Y6: =VLOOKUP(A6,A5:U672,2,FALSE) -> 49
A7: AK | B7: 36 | C7: 408 | D7: No | E7: Yes | F7: 30 | G7: 146.3 | H7: 128 | I7: 24.87 | J7: 162.5 | K7: 80 | L7: 13.81 | M7: 129.3 | N7: 109 | O7: 5.82 | P7: 14.5 | Q7: 6 | R7: 3.92 | S7: 0 | T7: FALSE | U7: =IF(G7>200,"High Usage","Normal Usage") -> Normal Usage | V7: =IF(AND(S7>3,D7="Yes"),"High Risk","Normal") -> Normal | W7: =IF(OR(S7>3,G7>250),"Potential Churn","Stable") -> Stable | X7: =IF(S7>5,"Critical",IF(S7>=3,"Medium","Low")) -> Low | Y7: =VLOOKUP(A7,A6:U673,2,FALSE) -> 36
A8: MI | B8: 65 | C8: 415 | D8: No | E8: No | F8: 0 | G8: 211.3 | H8: 120 | I8: 35.92 | J8: 162.6 | K8: 122 | L8: 13.82 | M8: 134.7 | N8: 118 | O8: 6.06 | P8: 13.2 | Q8: 5 | R8: 3.56 | S8: 3 | T8: FALSE | U8: =IF(G8>200,"High Usage","Normal Usage") -> High Usage | V8: =IF(AND(S8>3,D8="Yes"),"High Risk","Normal") -> Normal | W8: =IF(OR(S8>3,G8>250),"Potential Churn","Stable") -> Stable | X8: =IF(S8>5,"Critical",IF(S8>=3,"Medium","Low")) -> Medium | Y8: =VLOOKUP(A8,A7:U674,2,FALSE) -> 65
A9: ID | B9: 119 | C9: 415 | D9: No | E9: No | F9: 0 | G9: 159.1 | H9: 114 | I9: 27.05 | J9: 231.3 | K9: 117 | L9: 19.66 | M9: 143.2 | N9: 91 | O9: 6.44 | P9: 8.8 | Q9: 3 | R9: 2.38 | S9: 5 | T9: TRUE | U9: =IF(G9>200,"High Usage","Normal Usage") -> Normal Usage | V9: =IF(AND(S9>3,D9="Yes"),"High Risk","Normal") -> Normal | W9: =IF(OR(S9>3,G9>250),"Potential Churn","Stable") -> Potential Churn | X9: =IF(S9>5,"Critical",IF(S9>=3,"Medium","Low")) -> Medium | Y9: =VLOOKUP(A9,A8:U675,2,FALSE) -> 119
A10: VA | B10: 10 | C10: 408 | D10: No | E10: No | F10: 0 | G10: 186.1 | H10: 112 | I10: 31.64 | J10: 190.2 | K10: 66 | L10: 16.17 | M10: 282.8 | N10: 57 | O10: 12.73 | P10: 11.4 | Q10: 6 | R10: 3.08 | S10: 2 | T10: FALSE | U10: =IF(G10>200,"High Usage","Normal Usage") -> Normal Usage | V10: =IF(AND(S10>3,D10="Yes"),"High Risk","Normal") -> Normal | W10: =IF(OR(S10>3,G10>250),"Potential Churn","Stable") -> Stable | X10: =IF(S10>5,"Critical",IF(S10>=3,"Medium","Low")) -> Low | Y10: =VLOOKUP(A10,A9:U676,2,FALSE) -> 10
A11: WI | B11: 68 | C11: 415 | D11: No | E11: No | F11: 0 | G11: 148.8 | H11: 70 | I11: 25.3 | J11: 246.5 | K11: 164 | L11: 20.95 | M11: 129.8 | N11: 103 | O11: 5.84 | P11: 12.1 | Q11: 3 | R11: 3.27 | S11: 3 | T11: FALSE | U11: =IF(G11>200,"High Usage","Normal Usage") -> Normal Usage | V11: =IF(AND(S11>3,D11="Yes"),"High Risk","Normal") -> Normal | W11: =IF(OR(S11>3,G11>250),"Potential Churn","Stable") -> Stable | X11: =IF(S11>5,"Critical",IF(S11>=3,"Medium","Low")) -> Medium | Y11: =VLOOKUP(A11,A10:U677,2,FALSE) -> 68
A12: MN | B12: 74 | C12: 510 | D12: No | E12: Yes | F12: 33 | G12: 193.7 | H12: 91 | I12: 32.93 | J12: 246.1 | K12: 96 | L12: 20.92 | M12: 138 | N12: 92 | O12: 6.21 | P12: 14.6 | Q12: 3 | R12: 3.94 | S12: 2 | T12: FALSE | U12: =IF(G12>200,"High Usage","Normal Usage") -> Normal Usage | V12: =IF(AND(S12>3,D12="Yes"),"High Risk","Normal") -> Normal | W12: =IF(OR(S12>3,G12>250),"Potential Churn","Stable") -> Stable | X12: =IF(S12>5,"Critical",IF(S12>=3,"Medium","Low")) -> Low | Y12: =VLOOKUP(A12,A11:U678,2,FALSE) -> 74
A13: HI | B13: 85 | C13: 415 | D13: No | E13: No | F13: 0 | G13: 235.8 | H13: 109 | I13: 40.09 | J13: 157.2 | K13: 94 | L13: 13.36 | M13: 188.2 | N13: 99 | O13: 8.47 | P13: 12 | Q13: 3 | R13: 3.24 | S13: 0 | T13: FALSE | U13: =IF(G13>200,"High Usage","Normal Usage") -> High Usage | V13: =IF(AND(S13>3,D13="Yes"),"High Risk","Normal") -> Normal | W13: =IF(OR(S13>3,G13>250),"Potential Churn","Stable") -> Stable | X13: =IF(S13>5,"Critical",IF(S13>=3,"Medium","Low")) -> Low | Y13: =VLOOKUP(A13,A12:U679,2,FALSE) -> 85
... A668: CT | B668: 184 | C668: 510 | D668: Yes | E668: No | F668: 0 | G668: 213.8 | H668: 105 | I668: 36.35 | J668: 159.6 | K668: 84 | L668: 13.57 | M668: 139.2 | N668: 137 | O668: 6.26 | P668: 5 | Q668: 10 | R668: 1.35 | S668: 2 | T668: FALSE | U668: =IF(G668>200,"High Usage","Normal Usage") -> High Usage | V668: =IF(AND(S668>3,D668="Yes"),"High Risk","Normal") -> Normal | W668: =IF(OR(S668>3,G668>250),"Potential Churn","Stable") -> Stable | X668: =IF(S668>5,"Critical",IF(S668>=3,"Medium","Low")) -> Low | Y668: =VLOOKUP(A668,A667:U1334,2,FALSE) -> 184

Sheet VLOOKUP, XLOOKUP, INDEX+MATCH
A1: State | B1: Region Vlookup | C1: Region Xlookup | D1: Region Index + Match
A2: NY | B2: =VLOOKUP(A2,Sheet1!A1:T668,2,FALSE) -> 161 | C2: =_xlfn.XLOOKUP(A2,Sheet1!A1:A668,Sheet1!B1:B668,"NOT FOUND") -> 161 | D2: {=INDEX(Sheet1!B2:B668,MATCH(UPPER(TRIM(A2)),UPPER(Sheet1!A2:A668),0))} -> 161
A3: CA | B3: =VLOOKUP(A3,Sheet1!A2:T669,2,FALSE) -> 75 | C3: =_xlfn.XLOOKUP(A3,Sheet1!A2:A669,Sheet1!B2:B669,"NOT FOUND") -> 75 | D3: {=INDEX(Sheet1!B3:B669,MATCH(UPPER(TRIM(A3)),UPPER(Sheet1!A3:A669),0))} -> 75
A4: TX | B4: =VLOOKUP(A4,Sheet1!A3:T670,2,FALSE) -> 208 | C4: =_xlfn.XLOOKUP(A4,Sheet1!A3:A670,Sheet1!B3:B670,"NOT FOUND") -> 208 | D4: {=INDEX(Sheet1!B4:B670,MATCH(UPPER(TRIM(A4)),UPPER(Sheet1!A4:A670),0))} -> 208
A5: FL | B5: =VLOOKUP(A5,Sheet1!A4:T671,2,FALSE) -> 106 | C5: =_xlfn.XLOOKUP(A5,Sheet1!A4:A671,Sheet1!B4:B671,"NOT FOUND") -> 106 | D5: {=INDEX(Sheet1!B5:B671,MATCH(UPPER(TRIM(A5)),UPPER(Sheet1!A5:A671),0))} -> 106
A6: OH | B6: =VLOOKUP(A6,Sheet1!A5:T672,2,FALSE) -> 65 | C6: =_xlfn.XLOOKUP(A6,Sheet1!A5:A672,Sheet1!B5:B672,"NOT FOUND") -> 65 | D6: {=INDEX(Sheet1!B6:B672,MATCH(UPPER(TRIM(A6)),UPPER(Sheet1!A6:A672),0))} -> 65
A7: NJ | B7: =VLOOKUP(A7,Sheet1!A6:T673,2,FALSE) -> 95 | C7: =_xlfn.XLOOKUP(A7,Sheet1!A6:A673,Sheet1!B6:B673,"NOT FOUND") -> 95 | D7: {=INDEX(Sheet1!B7:B673,MATCH(UPPER(TRIM(A7)),UPPER(Sheet1!A7:A673),0))} -> 95
A8: PA | B8: =VLOOKUP(A8,Sheet1!A7:T674,2,FALSE) -> 82 | C8: =_xlfn.XLOOKUP(A8,Sheet1!A7:A674,Sheet1!B7:B674,"NOT FOUND") -> 82 | D8: {=INDEX(Sheet1!B8:B674,MATCH(UPPER(TRIM(A8)),UPPER(Sheet1!A8:A674),0))} -> 82
A9: MI | B9: =VLOOKUP(A9,Sheet1!A8:T675,2,FALSE) -> 65 | C9: =_xlfn.XLOOKUP(A9,Sheet1!A8:A675,Sheet1!B8:B675,"NOT FOUND") -> 65 | D9: {=INDEX(Sheet1!B9:B675,MATCH(UPPER(TRIM(A9)),UPPER(Sheet1!A9:A675),0))} -> 36
A10: GA | B10: =VLOOKUP(A10,Sheet1!A9:T676,2,FALSE) -> 107 | C10: =_xlfn.XLOOKUP(A10,Sheet1!A9:A676,Sheet1!B9:B676,"NOT FOUND") -> 107 | D10: {=INDEX(Sheet1!B10:B676,MATCH(UPPER(TRIM(A10)),UPPER(Sheet1!A10:A676),0))} -> 107
A11: NC | B11: =VLOOKUP(A11,Sheet1!A10:T677,2,FALSE) -> 155 | C11: =_xlfn.XLOOKUP(A11,Sheet1!A10:A677,Sheet1!B10:B677,"NOT FOUND") -> 155 | D11: {=INDEX(Sheet1!B11:B677,MATCH(UPPER(TRIM(A11)),UPPER(Sheet1!A11:A677),0))} -> 155

Sheet Array & Dynamic Functions
A1: Unique States | B1: Sorted States | C1: Sequence
A2: {=_xlfn.UNIQUE(Sheet1!A2:A668)} -> LA | B2: {=_xlfn._xlws.SORT(Sheet1!A2:A668)} -> AK | C2: {=_xlfn.SEQUENCE(600)} -> 1
A3: IN | B3: AK | C3: 2
A4: NY | B4: AK | C4: 3
A5: SC | B5: AK | C5: 4
A6: HI | B6: AK | C6: 5
A7: AK | B7: AK | C7: 6
A8: MI | B8: AK | C8: 7
A9: ID | B9: AK | C9: 8
A10: VA | B10: AK | C10: 9
A11: WI | B11: AL | C11: 10
A12: MN | B12: AL | C12: 11
A13: VT | B13: AL | C13: 12
A14: MT | B14: AL | C14: 13
... A52: GA | B52: CA | C52: 51
B53: CA | C53: 52
B54: CA | C54: 53
B55: CA | C55: 54
B56: CA | C56: 55
B57: CA | C57: 56
B58: CA | C58: 57
B59: CA | C59: 58
B60: CA | C60: 59
B61: CA | C61: 60
B62: CO | C62: 61
B63: CO | C63: 62
B64: CO | C64: 63
... B601: VT | C601: 600
B602: VT
B603: VT
B604: VT
B605: WA
B606: WA
B607: WA
B608: WA
B609: WA
B610: WA
B611: WA
B612: WA
B613: WA
...
