Workbook

Sheet Raw_Data
A1: State | B1: Account length | C1: Area code | D1: International plan | E1: Voice mail plan | F1: Number vmail messages | G1: Total day minutes | H1: Total day calls | I1: Total day charge | J1: Total eve minutes | K1: Total eve calls | L1: Total eve charge | M1: Total night minutes | N1: Total night calls | O1: Total night charge | P1: Total intl minutes | Q1: Total intl calls | R1: Total intl charge | S1: Customer service calls | T1: Churn
A2: LA | B2: 117 | C2: 408 | D2: No | E2: No | F2: 0 | G2: 184.5 | H2: 97 | I2: 31.37 | J2: 351.6 | K2: 80 | L2: 29.89 | M2: 215.8 | N2: 90 | O2: 9.71 | P2: 8.7 | Q2: 4 | R2: 2.35 | S2: 1 | T2: FALSE
A3: IN | B3: 65 | C3: 415 | D3: No | E3: No | F3: 0 | G3: 129.1 | H3: 137 | I3: 21.95 | J3: 228.5 | K3: 83 | L3: 19.42 | M3: 208.8 | N3: 111 | O3: 9.4 | P3: 12.7 | Q3: 6 | R3: 3.43 | S3: 4 | T3: TRUE
A4: NY | B4: 161 | C4: 415 | D4: No | E4: No | F4: 0 | G4: 332.9 | H4: 67 | I4: 56.59 | J4: 317.8 | K4: 97 | L4: 27.01 | M4: 160.6 | N4: 128 | O4: 7.23 | P4: 5.4 | Q4: 9 | R4: 1.46 | S4: 4 | T4: TRUE
A5: SC | B5: 111 | C5: 415 | D5: No | E5: No | F5: 0 | G5: 110.4 | H5: 103 | I5: 18.77 | J5: 137.3 | K5: 102 | L5: 11.67 | M5: 189.6 | N5: 105 | O5: 8.53 | P5: 7.7 | Q5: 6 | R5: 2.08 | S5: 2 | T5: FALSE
A6: HI | B6: 49 | C6: 510 | D6: No | E6: No | F6: 0 | G6: 119.3 | H6: 117 | I6: 20.28 | J6: 215.1 | K6: 109 | L6: 18.28 | M6: 178.7 | N6: 90 | O6: 8.04 | P6: 11.1 | Q6: 1 | R6: 3 | S6: 1 | T6: FALSE
A7: AK | B7: 36 | C7: 408 | D7: No | E7: Yes | F7: 30 | G7: 146.3 | H7: 128 | I7: 24.87 | J7: 162.5 | K7: 80 | L7: 13.81 | M7: 129.3 | N7: 109 | O7: 5.82 | P7: 14.5 | Q7: 6 | R7: 3.92 | S7: 0 | T7: FALSE
A8: MI | B8: 65 | C8: 415 | D8: No | E8: No | F8: 0 | G8: 211.3 | H8: 120 | I8: 35.92 | J8: 162.6 | K8: 122 | L8: 13.82 | M8: 134.7 | N8: 118 | O8: 6.06 | P8: 13.2 | Q8: 5 | R8: 3.56 | S8: 3 | T8: FALSE
A9: ID | B9: 119 | C9: 415 | D9: No | E9: No | F9: 0 | G9: 159.1 | H9: 114 | I9: 27.05 | J9: 231.3 | K9: 117 | L9: 19.66 | M9: 143.2 | N9: 91 | O9: 6.44 | P9: 8.8 | Q9: 3 | R9: 2.38 | S9: 5 | T9: TRUE
A10: VA | B10: 10 | C10: 408 | D10: No | E10: No | F10: 0 | G10: 186.1 | H10: 112 | I10: 31.64 | J10: 190.2 | K10: 66 | L10: 16.17 | M10: 282.8 | N10: 57 | O10: 12.73 | P10: 11.4 | Q10: 6 | R10: 3.08 | S10: 2 | T10: FALSE
A11: WI | B11: 68 | C11: 415 | D11: No | E11: No | F11: 0 | G11: 148.8 | H11: 70 | I11: 25.3 | J11: 246.5 | K11: 164 | L11: 20.95 | M11: 129.8 | N11: 103 | O11: 5.84 | P11: 12.1 | Q11: 3 | R11: 3.27 | S11: 3 | T11: FALSE
A12: MN | B12: 74 | C12: 510 | D12: No | E12: Yes | F12: 33 | G12: 193.7 | H12: 91 | I12: 32.93 | J12: 246.1 | K12: 96 | L12: 20.92 | M12: 138 | N12: 92 | O12: 6.21 | P12: 14.6 | Q12: 3 | R12: 3.94 | S12: 2 | T12: FALSE
A13: HI | B13: 85 | C13: 415 | D13: No | E13: No | F13: 0 | G13: 235.8 | H13: 109 | I13: 40.09 | J13: 157.2 | K13: 94 | L13: 13.36 | M13: 188.2 | N13: 99 | O13: 8.47 | P13: 12 | Q13: 3 | R13: 3.24 | S13: 0 | T13: FALSE
... A668: CT | B668: 184 | C668: 510 | D668: Yes | E668: No | F668: 0 | G668: 213.8 | H668: 105 | I668: 36.35 | J668: 159.6 | K668: 84 | L668: 13.57 | M668: 139.2 | N668: 137 | O668: 6.26 | P668: 5 | Q668: 10 | R668: 1.35 | S668: 2 | T668: FALSE

Sheet Clean_Data
A1: State | B1: Account length | C1: Area code | D1: International plan | E1: Voice mail plan | F1: Number vmail messages | G1: Total day minutes | H1: Total day calls | I1: Total day charge | J1: Total eve minutes | K1: Total eve calls | L1: Total eve charge | M1: Total night minutes | N1: Total night calls | O1: Total night charge | P1: Total intl minutes | Q1: Total intl calls | R1: Total intl charge | S1: Customer service calls | T1: Churn | U1: Clean State
A2: LA | B2: 117 | C2: 408 | D2: No | E2: No | F2: 0 | G2: 184.5 | H2: 97 | I2: 31.37 | J2: 351.6 | K2: 80 | L2: 29.89 | M2: 215.8 | N2: 90 | O2: 9.71 | P2: 8.7 | Q2: 4 | R2: 2.35 | S2: 1 | T2: FALSE | U2: =TRIM(A2) -> LA
A3: IN | B3: 65 | C3: 415 | D3: No | E3: No | F3: 0 | G3: 129.1 | H3: 137 | I3: 21.95 | J3: 228.5 | K3: 83 | L3: 19.42 | M3: 208.8 | N3: 111 | O3: 9.4 | P3: 12.7 | Q3: 6 | R3: 3.43 | S3: 4 | T3: TRUE | U3: IN
A4: NY | B4: 161 | C4: 415 | D4: No | E4: No | F4: 0 | G4: 332.9 | H4: 67 | I4: 56.59 | J4: 317.8 | K4: 97 | L4: 27.01 | M4: 160.6 | N4: 128 | O4: 7.23 | P4: 5.4 | Q4: 9 | R4: 1.46 | S4: 4 | T4: TRUE | U4: NY
A5: SC | B5: 111 | C5: 415 | D5: No | E5: No | F5: 0 | G5: 110.4 | H5: 103 | I5: 18.77 | J5: 137.3 | K5: 102 | L5: 11.67 | M5: 189.6 | N5: 105 | O5: 8.53 | P5: 7.7 | Q5: 6 | R5: 2.08 | S5: 2 | T5: FALSE | U5: SC
A6: HI | B6: 49 | C6: 510 | D6: No | E6: No | F6: 0 | G6: 119.3 | H6: 117 | I6: 20.28 | J6: 215.1 | K6: 109 | L6: 18.28 | M6: 178.7 | N6: 90 | O6: 8.04 | P6: 11.1 | Q6: 1 | R6: 3 | S6: 1 | T6: FALSE | U6: HI
A7: AK | B7: 36 | C7: 408 | D7: No | E7: Yes | F7: 30 | G7: 146.3 | H7: 128 | I7: 24.87 | J7: 162.5 | K7: 80 | L7: 13.81 | M7: 129.3 | N7: 109 | O7: 5.82 | P7: 14.5 | Q7: 6 | R7: 3.92 | S7: 0 | T7: FALSE | U7: =TRIM(A7) -> AK
A8: MI | B8: 65 | C8: 415 | D8: No | E8: No | F8: 0 | G8: 211.3 | H8: 120 | I8: 35.92 | J8: 162.6 | K8: 122 | L8: 13.82 | M8: 134.7 | N8: 118 | O8: 6.06 | P8: 13.2 | Q8: 5 | R8: 3.56 | S8: 3 | T8: FALSE | U8: MI
A9: ID | B9: 119 | C9: 415 | D9: No | E9: No | F9: 0 | G9: 159.1 | H9: 114 | I9: 27.05 | J9: 231.3 | K9: 117 | L9: 19.66 | M9: 143.2 | N9: 91 | O9: 6.44 | P9: 8.8 | Q9: 3 | R9: 2.38 | S9: 5 | T9: TRUE | U9: ID
A10: VA | B10: 10 | C10: 408 | D10: No | E10: No | F10: 0 | G10: 186.1 | H10: 112 | I10: 31.64 | J10: 190.2 | K10: 66 | L10: 16.17 | M10: 282.8 | N10: 57 | O10: 12.73 | P10: 11.4 | Q10: 6 | R10: 3.08 | S10: 2 | T10: FALSE | U10: VA
A11: WI | B11: 68 | C11: 415 | D11: No | E11: No | F11: 0 | G11: 148.8 | H11: 70 | I11: 25.3 | J11: 246.5 | K11: 164 | L11: 20.95 | M11: 129.8 | N11: 103 | O11: 5.84 | P11: 12.1 | Q11: 3 | R11: 3.27 | S11: 3 | T11: FALSE | U11: WI
A12: MN | B12: 74 | C12: 510 | D12: No | E12: Yes | F12: 33 | G12: 193.7 | H12: 91 | I12: 32.93 | J12: 246.1 | K12: 96 | L12: 20.92 | M12: 138 | N12: 92 | O12: 6.21 | P12: 14.6 | Q12: 3 | R12: 3.94 | S12: 2 | T12: FALSE | U12: MN
A13: HI | B13: 85 | C13: 415 | D13: No | E13: No | F13: 0 | G13: 235.8 | H13: 109 | I13: 40.09 | J13: 157.2 | K13: 94 | L13: 13.36 | M13: 188.2 | N13: 99 | O13: 8.47 | P13: 12 | Q13: 3 | R13: 3.24 | S13: 0 | T13: FALSE | U13: HI
A14: MN | B14: 46 | C14: 415 | D14: No | E14: No | F14: 0 | G14: 214.1 | H14: 72 | I14: 36.4 | J14: 164.4 | K14: 104 | L14: 13.97 | M14: 177.5 | N14: 113 | O14: 7.99 | P14: 8.2 | Q14: 3 | R14: 2.21 | S14: 2 | T14: FALSE | U14: MN
A15: VT | B15: 128 | C15: 510 | D15: No | E15: Yes | F15: 29 | G15: 179.3 | H15: 104 | I15: 30.48 | J15: 225.9 | K15: 86 | L15: 19.2 | M15: 323 | N15: 78 | O15: 14.54 | P15: 8.6 | Q15: 7 | R15: 2.32 | S15: 0 | T15: FALSE | U15: VT
A16: LA | B16: 155 | C16: 415 | D16: No | E16: No | F16: 0 | G16: 203.4 | H16: 100 | I16: 34.58 | J16: 190.9 | K16: 104 | L16: 16.23 | M16: 196 | N16: 119 | O16: 8.82 | P16: 8.9 | Q16: 4 | R16: 2.4 | S16: 0 | T16: TRUE | U16: LA
A17: MT | B17: 73 | C17: 415 | D17: No | E17: No | F17: 0 | G17: 160.1 | H17: 110 | I17: 27.22 | J17: 213.3 | K17: 72 | L17: 18.13 | M17: 174.1 | N17: 72 | O17: 7.83 | P17: 13 | Q17: 4 | R17: 3.51 | S17: 0 | T17: FALSE | U17: MT
A18: ID | B18: 77 | C18: 415 | D18: No | E18: No | F18: 0 | G18: 251.8 | H18: 72 | I18: 42.81 | J18: 205.7 | K18: 126 | L18: 17.48 | M18: 275.2 | N18: 109 | O18: 12.38 | P18: 9.8 | Q18: 7 | R18: 2.65 | S18: 2 | T18: TRUE | U18: ID
A19: MA | B19: 108 | C19: 415 | D19: No | E19: No | F19: 0 | G19: 178.3 | H19: 137 | I19: 30.31 | J19: 189 | K19: 76 | L19: 16.07 | M19: 129.1 | N19: 102 | O19: 5.81 | P19: 14.6 | Q19: 5 | R19: 3.94 | S19: 0 | T19: FALSE | U19: MA
... A668: CT | B668: 184 | C668: 510 | D668: Yes | E668: No | F668: 0 | G668: 213.8 | H668: 105 | I668: 36.35 | J668: 159.6 | K668: 84 | L668: 13.57 | M668: 139.2 | N668: 137 | O668: 6.26 | P668: 5 | Q668: 10 | R668: 1.35 | S668: 2 | T668: FALSE | U668: CT

Sheet Churn_by_State
A1: State | B1: FALSE | C1: TRUE
A2: AK | B2: =COUNTIFS(Clean_Data!A2:A668,A2,Clean_Data!T2:T668,FALSE) -> 9 | C2: =COUNTIFS(Clean_Data!A2:A668,A2,Clean_Data!T2:T668,TRUE) -> 0
A3: AL | B3: =COUNTIFS(Clean_Data!A3:A669,A3,Clean_Data!T3:T669,FALSE) -> 13 | C3: =COUNTIFS(Clean_Data!A3:A669,A3,Clean_Data!T3:T669,TRUE) -> 1
A4: AR | B4: =COUNTIFS(Clean_Data!A4:A670,A4,Clean_Data!T4:T670,FALSE) -> 8 | C4: =COUNTIFS(Clean_Data!A4:A670,A4,Clean_Data!T4:T670,TRUE) -> 0
A5: AZ | B5: =COUNTIFS(Clean_Data!A5:A671,A5,Clean_Data!T5:T671,FALSE) -> 18 | C5: =COUNTIFS(Clean_Data!A5:A671,A5,Clean_Data!T5:T671,TRUE) -> 1
A6: CA | B6: =COUNTIFS(Clean_Data!A6:A672,A6,Clean_Data!T6:T672,FALSE) -> 6 | C6: =COUNTIFS(Clean_Data!A6:A672,A6,Clean_Data!T6:T672,TRUE) -> 4
A7: CO | B7: =COUNTIFS(Clean_Data!A7:A673,A7,Clean_Data!T7:T673,FALSE) -> 5 | C7: =COUNTIFS(Clean_Data!A7:A673,A7,Clean_Data!T7:T673,TRUE) -> 2
A8: CT | B8: =COUNTIFS(Clean_Data!A8:A674,A8,Clean_Data!T8:T674,FALSE) -> 14 | C8: =COUNTIFS(Clean_Data!A8:A674,A8,Clean_Data!T8:T674,TRUE) -> 1
A9: DC | B9: =COUNTIFS(Clean_Data!A9:A675,A9,Clean_Data!T9:T675,FALSE) -> 9 | C9: =COUNTIFS(Clean_Data!A9:A675,A9,Clean_Data!T9:T675,TRUE) -> 0
A10: DE | B10: =COUNTIFS(Clean_Data!A10:A676,A10,Clean_Data!T10:T676,FALSE) -> 9 | C10: =COUNTIFS(Clean_Data!A10:A676,A10,Clean_Data!T10:T676,TRUE) -> 1
A11: FL | B11: =COUNTIFS(Clean_Data!A11:A677,A11,Clean_Data!T11:T677,FALSE) -> 8 | C11: =COUNTIFS(Clean_Data!A11:A677,A11,Clean_Data!T11:T677,TRUE) -> 1
A12: GA | B12: =COUNTIFS(Clean_Data!A12:A678,A12,Clean_Data!T12:T678,FALSE) -> 5 | C12: =COUNTIFS(Clean_Data!A12:A678,A12,Clean_Data!T12:T678,TRUE) -> 0
A13: HI | B13: =COUNTIFS(Clean_Data!A13:A679,A13,Clean_Data!T13:T679,FALSE) -> 7 | C13: =COUNTIFS(Clean_Data!A13:A679,A13,Clean_Data!T13:T679,TRUE) -> 1
... A52: WY | B52: =COUNTIFS(Clean_Data!A52:A718,A52,Clean_Data!T52:T718,FALSE) -> 9 | C52: =COUNTIFS(Clean_Data!A52:A718,A52,Clean_Data!T52:T718,TRUE) -> 1

Sheet Usage_by_Plan
A1: International plan | B1: Total day minutes
A2: No | B2: =AVERAGEIF(Raw_Data!D2:D668,"No",Raw_Data!G2:G668) -> 180.1184
A3: Yes | B3: =AVERAGEIF(Raw_Data!D2:D669,"Yes",Raw_Data!G2:G669) -> 190.56038

Sheet Support_vs_Churn
A1: Customer service calls | B1: FALSE | C1: TRUE
A2: 0 | B2: =COUNTIFS(Raw_Data!S2:S668,A2,Raw_Data!T2:T668,FALSE) -> 129 | C2: =COUNTIFS(Raw_Data!S2:S668,A2,Raw_Data!T2:T668,TRUE) -> 13
A3: 1 | B3: =COUNTIFS(Raw_Data!S3:S669,A3,Raw_Data!T3:T669,FALSE) -> 212 | C3: =COUNTIFS(Raw_Data!S3:S669,A3,Raw_Data!T3:T669,TRUE) -> 23
A4: 2 | B4: =COUNTIFS(Raw_Data!S4:S670,A4,Raw_Data!T4:T670,FALSE) -> 126 | C4: =COUNTIFS(Raw_Data!S4:S670,A4,Raw_Data!T4:T670,TRUE) -> 25
A5: 3 | B5: =COUNTIFS(Raw_Data!S5:S671,A5,Raw_Data!T5:T671,FALSE) -> 74 | C5: =COUNTIFS(Raw_Data!S5:S671,A5,Raw_Data!T5:T671,TRUE) -> 7
A6: 4 | B6: =COUNTIFS(Raw_Data!S6:S672,A6,Raw_Data!T6:T672,FALSE) -> 21 | C6: =COUNTIFS(Raw_Data!S6:S672,A6,Raw_Data!T6:T672,TRUE) -> 10
A7: 5 | B7: =COUNTIFS(Raw_Data!S7:S673,A7,Raw_Data!T7:T673,FALSE) -> 6 | C7: =COUNTIFS(Raw_Data!S7:S673,A7,Raw_Data!T7:T673,TRUE) -> 11
A8: 6 | B8: =COUNTIFS(Raw_Data!S8:S674,A8,Raw_Data!T8:T674,FALSE) -> 1 | C8: =COUNTIFS(Raw_Data!S8:S674,A8,Raw_Data!T8:T674,TRUE) -> 4
A9: 7 | B9: =COUNTIFS(Raw_Data!S9:S675,A9,Raw_Data!T9:T675,FALSE) -> 1 | C9: =COUNTIFS(Raw_Data!S9:S675,A9,Raw_Data!T9:T675,TRUE) -> 0
A10: 8 | B10: =COUNTIFS(Raw_Data!S10:S676,A10,Raw_Data!T10:T676,FALSE) -> 1 | C10: =COUNTIFS(Raw_Data!S10:S676,A10,Raw_Data!T10:T676,TRUE) -> 0

Sheet Statistics
A1: Metric | B1: Value
A2: Average Day Minutes | B2: =AVERAGE(Raw_Data!G2:G668) -> 180.94813
A3: Max Day Minutes | B3: =MAX(Raw_Data!G2:G668) -> 334.3
A4: Min Day Minutes | B4: =MIN(Raw_Data!G2:G668) -> 25.9
A5: Count | B5: =COUNT(Raw_Data!G2:G668) -> 667

Sheet Povit Table
A3: Count of State | B3: Column Labels
A4: Row Labels | B4: FALSE | C4: TRUE | D4: Grand Total
A5: AK | B5: 9 | D5: 9 | F5: Row Labels | G5: Sum of Total day minutes | I5: Count of State | J5: Column Labels
A6: AL | B6: 13 | C6: 1 | D6: 14 | F6: No | G6: 110592.7 | I6: Row Labels | J6: FALSE | K6: TRUE | L6: Grand Total
A7: AR | B7: 8 | D7: 8 | F7: Yes | G7: 10099.7 | I7: 0 | J7: 129 | K7: 13 | L7: 142
A8: AZ | B8: 18 | C8: 1 | D8: 19 | F8: Grand Total | G8: 120692.4 | I8: 1 | J8: 213 | K8: 23 | L8: 236
A9: CA | B9: 6 | C9: 4 | D9: 10 | I9: 2 | J9: 126 | K9: 25 | L9: 151
A10: CO | B10: 5 | C10: 2 | D10: 7 | I10: 3 | J10: 74 | K10: 7 | L10: 81
A11: CT | B11: 14 | C11: 1 | D11: 15 | I11: 4 | J11: 21 | K11: 12 | L11: 33
A12: DC | B12: 9 | D12: 9 | I12: 5 | J12: 6 | K12: 11 | L12: 17
A13: DE | B13: 9 | C13: 1 | D13: 10 | I13: 6 | J13: 1 | K13: 4 | L13: 5
A14: FL | B14: 8 | C14: 1 | D14: 9 | I14: 7 | J14: 1 | L14: 1
A15: GA | B15: 5 | D15: 5 | I15: 8 | J15: 1 | L15: 1
A16: HI | B16: 8 | C16: 1 | D16: 9 | I16: Grand Total | J16: 572 | K16: 95 | L16: 667
A17: IA | B17: 6 | D17: 6
A18: ID | B18: 13 | C18: 4 | D18: 17
A19: IL | B19: 12 | C19: 1 | D19: 13
A20: IN | B20: 14 | C20: 3 | D20: 17
A21: KS | B21: 15 | C21: 3 | D21: 18
A22: KY | B22: 14 | C22: 2 | D22: 16
A23: LA | B23: 15 | C23: 1 | D23: 16
A24: MA | B24: 10 | C24: 3 | D24: 13
A25: MD | B25: 7 | C25: 3 | D25: 10
A26: ME | B26: 11 | C26: 2 | D26: 13
A27: MI | B27: 12 | C27: 3 | D27: 15
A28: MN | B28: 12 | C28: 2 | D28: 14
A29: MO | B29: 10 | C29: 2 | D29: 12
... A34: NE | B34: 15 | C34: 1 | D34: 16
A35: NH | B35: 13 | D35: 13
A36: NJ | B36: 14 | C36: 4 | D36: 18
A37: NM | B37: 16 | C37: 2 | D37: 18
A38: NV | B38: 4 | C38: 1 | D38: 5
A39: NY | B39: 12 | C39: 3 | D39: 15
A40: OH | B40: 12 | D40: 12
A41: OK | B41: 7 | C41: 2 | D41: 9
A42: OR | B42: 12 | C42: 4 | D42: 16
A43: PA | B43: 9 | D43: 9
A44: RI | B44: 14 | C44: 3 | D44: 17
A45: SC | B45: 8 | C45: 3 | D45: 11
A46: SD | B46: 9 | C46: 2 | D46: 11
...
